<?xml version="1.0" ?>
<robot name="turtlebot3_burger">
   <!-- xmlns:xacro="http://ros.org/wiki/xacro" <xacro:include filename="package://my_gazebo/urdf/common_properties.urdf"/> -->

  <!-- Init colour -->
  <material name="black">
      <color rgba="0.0 0.0 0.0 1.0"/>
  </material>

  <material name="dark">
    <color rgba="0.3 0.3 0.3 1.0"/>
  </material>

  <material name="light_black">
    <color rgba="0.4 0.4 0.4 1.0"/>
  </material>

  <material name="blue">
    <color rgba="0.0 0.0 0.8 1.0"/>
  </material>

  <material name="green">
    <color rgba="0.0 0.8 0.0 1.0"/>
  </material>

  <material name="grey">
    <color rgba="0.5 0.5 0.5 1.0"/>
  </material>

  <material name="orange">
    <color rgba="1.0 0.4235 0.0392 1.0"/>
  </material>

  <material name="brown">
    <color rgba="0.8706 0.8118 0.7647 1.0"/>
  </material>

  <material name="red">
    <color rgba="0.8 0.0 0.0 1.0"/>
  </material>

  <material name="white">
    <color rgba="1.0 1.0 1.0 1.0"/>
  </material>
<!-- Init colour -->

  <link name="base_footprint"/>

  <joint name="base_joint" type="fixed">
    <parent link="base_footprint"/>
    <child link="base_link"/>
    <origin xyz="0.0 0.0 0.010" rpy="0 0 0"/>
  </joint>

  <link name="base_link">
    <visual>
      <origin xyz="-0.032 0 0.0" rpy="0 0 0"/>
      <geometry>
        <mesh filename="package://my_gazebo/models/turtlebot3_common/meshes/burger_base.dae" scale="0.001 0.001 0.001"/>
      </geometry>
      <material name="light_black"/>
    </visual>
    <collision>
      <origin xyz="-0.032 0 0.070" rpy="0 0 0"/>
      <geometry>
        <box size="0.140 0.140 0.143"/>
      </geometry>
    </collision>
    <inertial>
      <origin xyz="0 0 0" rpy="0 0 0"/>
      <mass value="8.2573504e-01"/>
      <inertia ixx="2.2124416e-03" ixy="-1.2294101e-05" ixz="3.4938785e-05" iyy="2.1193702e-03" iyz="-5.0120904e-06" izz="2.0064271e-03" />
    </inertial>
  </link>

  <joint name="wheel_left_joint" type="continuous">
    <parent link="base_link"/>
    <child link="wheel_left_link"/>
    <origin xyz="0.0 0.08 0.023" rpy="-1.57 0 0"/>
    <axis xyz="0 0 1"/>
  </joint>

  <link name="wheel_left_link">
    <visual>
      <origin xyz="0 0 0" rpy="1.57 0 0"/>
      <geometry>
        <mesh filename="package://my_gazebo/models/insperbot/meshes/wheels/left_tire.dae" scale="0.001 0.001 0.001"/>
      </geometry>
      <material name="dark"/>
    </visual>
    <collision>
      <origin xyz="0 0 0" rpy="0 0 0"/>
      <geometry>
        <cylinder length="0.018" radius="0.033"/>
      </geometry>
    </collision>
    <inertial>
      <origin xyz="0 0 0" />
      <mass value="2.8498940e-02" />
      <inertia ixx="1.1175580e-05" ixy="-4.2369783e-11" ixz="-5.9381719e-09" iyy="1.1192413e-05" iyz="-1.4400107e-11" izz="2.0712558e-05" />
    </inertial>
  </link>

  <joint name="wheel_right_joint" type="continuous">
    <parent link="base_link"/>
    <child link="wheel_right_link"/>
    <origin xyz="0.0 -0.080 0.023" rpy="-1.57 0 0"/>
    <axis xyz="0 0 1"/>
  </joint>

  <link name="wheel_right_link">
    <visual>
      <origin xyz="0 0 0" rpy="1.57 0 0"/>
      <geometry>
        <mesh filename="package://my_gazebo/models/insperbot/meshes/wheels/right_tire.dae" scale="0.001 0.001 0.001"/>
      </geometry>
      <material name="dark"/>
    </visual>

    <collision>
      <origin xyz="0 0 0" rpy="0 0 0"/>
      <geometry>
        <cylinder length="0.018" radius="0.033"/>
      </geometry>
    </collision>

    <inertial>
      <origin xyz="0 0 0" />
      <mass value="2.8498940e-02" />
      <inertia ixx="1.1175580e-05" ixy="-4.2369783e-11" ixz="-5.9381719e-09" iyy="1.1192413e-05" iyz="-1.4400107e-11" izz="2.0712558e-05" />
    </inertial>
  </link>

  <joint name="caster_back_joint" type="fixed">
    <parent link="base_link"/>
    <child link="caster_back_link"/>
    <origin xyz="-0.081 0 -0.004" rpy="-1.57 0 0"/>
  </joint>

  <link name="caster_back_link">
    <collision>
      <origin xyz="0 0.001 0" rpy="0 0 0"/>
      <geometry>
        <box size="0.030 0.009 0.020"/>
      </geometry>
    </collision>

    <inertial>
      <origin xyz="0 0 0" />
      <mass value="0.005" />
      <inertia ixx="0.001" ixy="0.0" ixz="0.0" iyy="0.001" iyz="0.0" izz="0.001" />
    </inertial>
  </link>

  <joint name="imu_joint" type="fixed">
    <parent link="base_link"/>
    <child link="imu_link"/>
    <origin xyz="-0.032 0 0.068" rpy="0 0 0"/>
  </joint>

  <link name="imu_link"/>

  <joint name="scan_joint" type="fixed">
    <parent link="base_link"/>
    <child link="base_scan"/>
    <origin xyz="-0.032 0 0.172" rpy="0 0 0"/>
  </joint>

  <link name="base_scan">
    <visual>
      <origin xyz="0 0 0.0" rpy="0 0 0"/>
      <geometry>
        <mesh filename="package://my_gazebo/models/insperbot/meshes/sensors/lds.dae" scale="0.001 0.001 0.001"/>
      </geometry>
      <material name="dark"/>
    </visual>

    <collision>
      <origin xyz="0.015 0 -0.0065" rpy="0 0 0"/>
      <geometry>
        <cylinder length="0.0315" radius="0.055"/>
      </geometry>
    </collision>

    <inertial>
      <mass value="0.114" />
      <origin xyz="0 0 0" />
      <inertia ixx="0.001" ixy="0.0" ixz="0.0" iyy="0.001" iyz="0.0" izz="0.001" />
    </inertial>
  </link>


<!-- inicio da personalizacao insper -->

<!-- base_link_garra -->
<link name="base_link_garra">
  <inertial>
    <origin rpy="0 0 0" xyz="0.0005 -0.0001 0.002"/>
    <mass value="0.001"/>
    <inertia ixx="0" ixy="0" ixz="0" iyy="0" iyz="0" izz="0"/>
  </inertial>
  <collision name="base_link_garra_collision">
    <origin rpy="0 0 0" xyz="0 0 0"/>
    <geometry>
      <mesh filename="package://my_gazebo/models/insperbot/meshes/garra/base_link_garra.stl" scale="0.001 0.001 0.001"/>
    </geometry>
  </collision>
  <visual name="base_link_garra_visual">
    <origin rpy="0 0 0" xyz="0 0 0"/>
    <geometry>
      <mesh filename="package://my_gazebo/models/insperbot/meshes/garra/base_link_garra.stl" scale="0.001 0.001 0.001"/>
    </geometry>
  </visual>
</link>

<!-- lat31 -->
<link name="lat31">
  <inertial>
    <origin rpy="0 0 0" xyz="-0.005014384312211391 -0.0015000010654330244 0.013948367968184407"/>
    <mass value="0.001"/>
    <inertia ixx="0" ixy="0" ixz="0" iyy="0" iyz="0" izz="0"/>
  </inertial>
  <collision name="lat31_collision">
    <origin rpy="0 0 0" xyz="-0.007563 0.0205 -0.001"/>
    <geometry>
      <mesh filename="package://my_gazebo/models/insperbot/meshes/garra/lat31.stl" scale="0.001 0.001 0.001"/>
    </geometry>
  </collision>
  <visual name="lat31_visual">
    <origin rpy="0 0 0" xyz="-0.007563 0.0205 -0.001"/>
    <geometry>
      <mesh filename="package://my_gazebo/models/insperbot/meshes/garra/lat31.stl" scale="0.001 0.001 0.001"/>
    </geometry>
  </visual>
</link>

<!-- lat11 -->
<link name="lat11">
  <inertial>
    <origin rpy="0 0 0" xyz="-0.00149999999999997 0.004954936394439788 0.013948367968184407"/>
    <mass value="0.001"/>
    <inertia ixx="0" ixy="0" ixz="0" iyy="0" iyz="0" izz="0"/>
  </inertial>
  <collision name="lat11_collision">
    <origin rpy="0 0 0" xyz="0.016 0.0 -0.001"/>
    <geometry>
      <mesh filename="package://my_gazebo/models/insperbot/meshes/garra/lat11.stl" scale="0.001 0.001 0.001"/>
    </geometry>
  </collision>
  <visual name="lat11_visual">
    <origin rpy="0 0 0" xyz="0.016 0.0 -0.001"/>
    <geometry>
      <mesh filename="package://my_gazebo/models/insperbot/meshes/garra/lat11.stl" scale="0.001 0.001 0.001"/>
    </geometry>
  </visual>
</link>

<!-- lat21 -->
<link name="lat21">
  <inertial>
    <origin rpy="0 0 0" xyz="0.004954582993387833 0.0014999998509883788 0.013948367968184407"/>
    <mass value="0.001"/>
    <inertia ixx="0" ixy="0" ixz="0" iyy="0" iyz="0" izz="0"/>
  </inertial>
  <collision name="lat21_collision">
    <origin rpy="0 0 0" xyz="0.002445 -0.0205 -0.001"/>
    <geometry>
      <mesh filename="package://my_gazebo/models/insperbot/meshes/garra/lat21.stl" scale="0.001 0.001 0.001"/>
    </geometry>
  </collision>
  <visual name="lat21_visual">
    <origin rpy="0 0 0" xyz="0.002445 -0.0205 -0.001"/>
    <geometry>
      <mesh filename="package://my_gazebo/models/insperbot/meshes/garra/lat21.stl" scale="0.001 0.001 0.001"/>
    </geometry>
  </visual>
</link>

<!-- servo_garra1 -->
  <link name="servo_garra1">
  <inertial>
    <origin rpy="0 0 0" xyz="0.0003331581426503209 0.00010673599128592421 0.010000547183940757"/>
    <mass value="0.001"/>
    <inertia ixx="0" ixy="0" ixz="0" iyy="0" iyz="0" izz="0"/>
  </inertial>
  <collision name="servo_garra1_collision">
    <origin rpy="0 0 0" xyz="-0.003609 5.8e-05 -0.004"/>
    <geometry>
      <mesh filename="package://my_gazebo/models/insperbot/meshes/garra/servo_garra1.stl" scale="0.001 0.001 0.001"/>
    </geometry>
  </collision>
  <visual name="servo_garra1_visual">
    <origin rpy="0 0 0" xyz="-0.003609 5.8e-05 -0.004"/>
    <geometry>
      <mesh filename="package://my_gazebo/models/insperbot/meshes/garra/servo_garra1.stl" scale="0.001 0.001 0.001"/>
    </geometry>
  </visual>
</link>

<!-- base_camera1 -->
<link name="base_camera1">
  <inertial>
    <origin rpy="0 0 0" xyz="-0.004389339547781822 0.020361286436828687 0.001500000342726699"/>
    <mass value="0.001"/>
    <inertia ixx="0" ixy="0" ixz="0" iyy="0" iyz="0" izz="0"/>
  </inertial>
  <collision name="base_camera1_collision">
    <origin xyz="0.083 -0.005 0.092" rpy="0 0 0"/>
    <geometry>
      <mesh filename="package://my_gazebo/models/insperbot/meshes/garra/base_camera1.stl" scale="0.001 0.001 0.001"/>
    </geometry>
  </collision>
  <visual name="base_camera1_visual">
    <origin xyz="0.043 0.0015 0.092" rpy="0 0 -1.57"/>
    <geometry>
      <mesh filename="package://my_gazebo/models/insperbot/meshes/garra/base_camera1.stl" scale="0.001 0.001 0.001"/>
    </geometry>
  </visual>
</link>

<link name="garra1garrabraco1">
  <inertial>
    <origin rpy="0 0 0" xyz="-0.0037506353032803787 0.05642585700103959 0.0018237999124817317"/>
    <mass value="0.00285"/>
    <inertia ixx="1.1175580e-05" ixy="0" ixz="0" iyy="1.1192413e-05" iyz="0" izz="2.0712558e-05"/>
  </inertial>
  <visual name="garra1garrabraco1_visual">
    <origin rpy="0 0 0" xyz="-0.027109 -0.009942 -0.014"/>
    <geometry>
      <mesh filename="package://my_gazebo/models/insperbot/meshes/garra/arm.dae" scale="0.001 0.001 0.001"/>
    </geometry>
  </visual>
  <collision name="garra1garrabraco1_collision">
    <origin rpy="0 0 0" xyz="-0.027109 -0.009942 -0.014"/>
    <geometry>
      <mesh filename="package://my_gazebo/models/insperbot/meshes/garra/arm.dae" scale="0.001 0.001 0.001"/>
    </geometry>
  </collision>
</link>

<!-- juncoes personalizacao insper -->
<joint name="base_link_garra_joint" type="fixed">
  <parent link="base_link"/>
  <child link="base_link_garra"/>
  <origin xyz="0.043 0.0022 0.093" rpy="0 0 -1.57"/>
</joint>

<joint name="lat31_joint" type="fixed">
  <parent link="base_link_garra"/>
  <child link="lat31"/>
  <origin xyz="0.045 0.042 0.092" rpy="0 0 0"/>
</joint>

<joint name="lat11_joint" type="fixed">
  <parent link="base_link_garra"/>
  <child link="lat11"/>
  <origin xyz="0.083 -0.005 0.092" rpy="0 0 0"/>
</joint>

<joint name="lat21_joint" type="fixed">
  <parent link="base_link_garra"/>
  <child link="lat21"/>
  <origin xyz="0.083 -0.005 0.092" rpy="0 0 0"/>
</joint>

<joint name="servo_garra1_joint" type="fixed">
  <parent link="base_link_garra"/>
  <child link="servo_garra1"/>
  <origin xyz="0.083 -0.005 0.092" rpy="0 0 0"/>
</joint>

<joint name="base_camera1_joint" type="fixed">
  <parent link="base_link_garra"/>
  <child link="base_camera1"/>
  <origin xyz="0.083 -0.005 0.092" rpy="0 0 0"/>
</joint>



  <joint name="joint1" type="revolute">
    <parent link="servo_garra1"/>
    <child link="garra1garrabraco1"/>
    <origin xyz="0 0 0" rpy="0 0 0"/>
    <axis xyz="1 0 0"/>
    <limit lower="-1.57" upper="1.57" effort="10" velocity="1.0"/>
    <dynamics damping="0.1" friction="0.0"/>
  </joint>

<transmission name="joint1_tran">
  <type>transmission_interface/SimpleTransmission</type>
  <joint name="joint1">
    <hardwareInterface>effort</hardwareInterface>
  </joint>
  <actuator name="joint1_actr">
    <hardwareInterface>effort</hardwareInterface>
    <mechanicalReduction>1</mechanicalReduction>
  </actuator>
</transmission>

  <ros2_control name="GazeboSystem" type="system">
    <hardware>
      <plugin>gazebo_ros2_control/GazeboSystem</plugin>
    </hardware>
    <joint name="joint1">
      <command_interface name="position"/>
      <state_interface name="position"/>
      <state_interface name="velocity"/>
      <state_interface name="effort"/>
    </joint>
  </ros2_control>



</robot>
